Rasa process starting
/home/hticdeep/anaconda3/envs/torch3/lib/python3.6/site-packages/rasa_nlu/extractors/entity_synonyms.py:85: UserWarning: Failed to load synonyms file from '/media/hticdeep/drive3/shyam/IDAI/RASA/Gere_version2/models/nlu/default/GereV2/entity_synonyms.json'
  "".format(entity_synonyms_file))

Restoring parameters from /media/hticdeep/drive3/shyam/IDAI/RASA/Gere_version2/models/nlu/default/GereV2/intent_classifier_tensorflow_embedding.ckpt
/home/hticdeep/anaconda3/envs/torch3/lib/python3.6/site-packages/pykwalify/core.py:99: UnsafeLoaderWarning: 
The default 'Loader' for 'load(stream)' without further arguments can be unsafe.
Use 'load(stream, Loader=ruamel.yaml.Loader)' explicitly if that is OK.
Alternatively include the following in your code:

  import warnings
  warnings.simplefilter('ignore', ruamel.yaml.error.UnsafeLoaderWarning)

In most other cases you should consider using 'safe_load(stream)'
  data = yaml.load(stream)

Available web server routes: 
hello                                              OPTIONS, GET, HEAD             /
list_trackers                                      OPTIONS, GET, HEAD             /conversations
execute_action                                     OPTIONS, POST                  /conversations/[sender_id]/execute
log_message                                        OPTIONS, POST                  /conversations/[sender_id]/messages
predict                                            OPTIONS, POST                  /conversations/[sender_id]/predict
respond                                            OPTIONS, POST, GET, HEAD       /conversations/[sender_id]/respond
retrieve_story                                     OPTIONS, GET, HEAD             /conversations/[sender_id]/story
retrieve_tracker                                   OPTIONS, GET, HEAD             /conversations/[sender_id]/tracker
replace_events                                     OPTIONS, PUT                   /conversations/[sender_id]/tracker/events
get_domain                                         OPTIONS, GET, HEAD             /domain
evaluate_stories                                   OPTIONS, POST                  /evaluate
continue_training                                  OPTIONS, POST                  /finetune
load_model                                         OPTIONS, POST                  /model
tracker_predict                                    OPTIONS, POST                  /predict
static                                             OPTIONS, GET, HEAD             /static/[filename]
status                                             OPTIONS, GET, HEAD             /status
version                                            OPTIONS, GET, HEAD             /version
custom_webhook_CmdlineInput.health                 OPTIONS, GET, HEAD             /webhooks/rest/
custom_webhook_CmdlineInput.receive                OPTIONS, POST                  /webhooks/rest/webhook
Rasa Core server is up and running on http://localhost:5005
Creating a new tracker for id 'default'.
Received user message 'hey' with intent '{'name': 'greet', 'confidence': 0.9688786864280701}' and entities '[]'
Logged UserUtterance - tracker now has 2 events
Current slot values: 
	add_on: None
	bath_utilities: None
	electrical device: None
	object: None
	person_maid: None
	service: None
	substance: None
	time: None
	w_service: None
Current tracker state [None, None, None, {}, {'prev_action_listen': 1.0, 'intent_greet': 1.0}]
There is a memorised next action '19'
Predicted next action using policy_0_MemoizationPolicy
Predicted next action 'utter_greet' with prob 1.00.
Action 'utter_greet' ended with events '[]'
Bot utterance 'BotUttered(text: Hey buddy! Welcome! How can I help you! Service we provide |Bookings - Cab, Gas| |Service - Electricity, Carpenting, Plumbing, Water, Maid| |Add_ons - Add water|, data: {
  "elements": null,
  "buttons": null,
  "attachment": null
})'
Current tracker state [None, None, {}, {'prev_action_listen': 1.0, 'intent_greet': 1.0}, {'prev_utter_greet': 1.0, 'intent_greet': 1.0}]
There is a memorised next action '0'
Predicted next action using policy_0_MemoizationPolicy
Predicted next action 'action_listen' with prob 1.00.
Action 'action_listen' ended with events '[]'
Recreating tracker for id 'default'
Received user message 'book a mathase' with intent '{'name': 'booking', 'confidence': 0.9764930605888367}' and entities '[]'
Logged UserUtterance - tracker now has 6 events
Current slot values: 
	add_on: None
	bath_utilities: None
	electrical device: None
	object: None
	person_maid: None
	service: None
	substance: None
	time: None
	w_service: None
Current tracker state [None, {}, {'prev_action_listen': 1.0, 'intent_greet': 1.0}, {'prev_utter_greet': 1.0, 'intent_greet': 1.0}, {'intent_booking': 1.0, 'prev_action_listen': 1.0}]
There is a memorised next action '16'
Predicted next action using policy_0_MemoizationPolicy
Predicted next action 'action_slots' with prob 1.00.
Encountered an exception while running action 'action_slots'. Bot will continue, but the actions events are lost. Make sure to fix the exception in your custom code.
The model predicted the custom action 'action_slots' but you didn't configure an endpoint to run this custom action. Please take a look at the docs and set an endpoint configuration. https://rasa.com/docs/core/customactions/
Traceback (most recent call last):
  File "/home/hticdeep/anaconda3/envs/torch3/lib/python3.6/site-packages/rasa_core/processor.py", line 351, in _run_action
    events = action.run(dispatcher, tracker, self.domain)
  File "/home/hticdeep/anaconda3/envs/torch3/lib/python3.6/site-packages/rasa_core/actions/action.py", line 321, in run
    "".format(self.name(), DOCS_BASE_URL))
Exception: The model predicted the custom action 'action_slots' but you didn't configure an endpoint to run this custom action. Please take a look at the docs and set an endpoint configuration. https://rasa.com/docs/core/customactions/
Action 'action_slots' ended with events '[]'
Current tracker state [{}, {'prev_action_listen': 1.0, 'intent_greet': 1.0}, {'prev_utter_greet': 1.0, 'intent_greet': 1.0}, {'intent_booking': 1.0, 'prev_action_listen': 1.0}, {'intent_booking': 1.0, 'prev_action_slots': 1.0}]
There is a memorised next action '0'
Predicted next action using policy_0_MemoizationPolicy
Predicted next action 'action_listen' with prob 1.00.
Action 'action_listen' ended with events '[]'
Rasa process starting
/home/hticdeep/anaconda3/envs/torch3/lib/python3.6/site-packages/rasa_nlu/extractors/entity_synonyms.py:85: UserWarning: Failed to load synonyms file from '/media/hticdeep/drive3/shyam/IDAI/RASA/Gere_version2/models/nlu/default/GereV2/entity_synonyms.json'
  "".format(entity_synonyms_file))

Restoring parameters from /media/hticdeep/drive3/shyam/IDAI/RASA/Gere_version2/models/nlu/default/GereV2/intent_classifier_tensorflow_embedding.ckpt
/home/hticdeep/anaconda3/envs/torch3/lib/python3.6/site-packages/pykwalify/core.py:99: UnsafeLoaderWarning: 
The default 'Loader' for 'load(stream)' without further arguments can be unsafe.
Use 'load(stream, Loader=ruamel.yaml.Loader)' explicitly if that is OK.
Alternatively include the following in your code:

  import warnings
  warnings.simplefilter('ignore', ruamel.yaml.error.UnsafeLoaderWarning)

In most other cases you should consider using 'safe_load(stream)'
  data = yaml.load(stream)

Rasa Core server is up and running on http://localhost:5005
Encountered an exception while running action 'action_slots'. Bot will continue, but the actions events are lost. Make sure to fix the exception in your custom code.
The model predicted the custom action 'action_slots' but you didn't configure an endpoint to run this custom action. Please take a look at the docs and set an endpoint configuration. https://rasa.com/docs/core/customactions/
Traceback (most recent call last):
  File "/home/hticdeep/anaconda3/envs/torch3/lib/python3.6/site-packages/rasa_core/processor.py", line 351, in _run_action
    events = action.run(dispatcher, tracker, self.domain)
  File "/home/hticdeep/anaconda3/envs/torch3/lib/python3.6/site-packages/rasa_core/actions/action.py", line 321, in run
    "".format(self.name(), DOCS_BASE_URL))
Exception: The model predicted the custom action 'action_slots' but you didn't configure an endpoint to run this custom action. Please take a look at the docs and set an endpoint configuration. https://rasa.com/docs/core/customactions/
Rasa process starting
/home/hticdeep/anaconda3/envs/torch3/lib/python3.6/site-packages/rasa_nlu/extractors/entity_synonyms.py:85: UserWarning: Failed to load synonyms file from '/media/hticdeep/drive3/shyam/IDAI/RASA/Gere_version2/models/nlu/default/GereV2/entity_synonyms.json'
  "".format(entity_synonyms_file))

Restoring parameters from /media/hticdeep/drive3/shyam/IDAI/RASA/Gere_version2/models/nlu/default/GereV2/intent_classifier_tensorflow_embedding.ckpt
/home/hticdeep/anaconda3/envs/torch3/lib/python3.6/site-packages/pykwalify/core.py:99: UnsafeLoaderWarning: 
The default 'Loader' for 'load(stream)' without further arguments can be unsafe.
Use 'load(stream, Loader=ruamel.yaml.Loader)' explicitly if that is OK.
Alternatively include the following in your code:

  import warnings
  warnings.simplefilter('ignore', ruamel.yaml.error.UnsafeLoaderWarning)

In most other cases you should consider using 'safe_load(stream)'
  data = yaml.load(stream)

Rasa Core server is up and running on http://localhost:5005
Rasa process starting
/home/hticdeep/anaconda3/envs/torch3/lib/python3.6/site-packages/rasa_nlu/extractors/entity_synonyms.py:85: UserWarning: Failed to load synonyms file from '/media/hticdeep/drive3/shyam/IDAI/RASA/Gere_version2/models/nlu/default/GereV2/entity_synonyms.json'
  "".format(entity_synonyms_file))

Restoring parameters from /media/hticdeep/drive3/shyam/IDAI/RASA/Gere_version2/models/nlu/default/GereV2/intent_classifier_tensorflow_embedding.ckpt
/home/hticdeep/anaconda3/envs/torch3/lib/python3.6/site-packages/pykwalify/core.py:99: UnsafeLoaderWarning: 
The default 'Loader' for 'load(stream)' without further arguments can be unsafe.
Use 'load(stream, Loader=ruamel.yaml.Loader)' explicitly if that is OK.
Alternatively include the following in your code:

  import warnings
  warnings.simplefilter('ignore', ruamel.yaml.error.UnsafeLoaderWarning)

In most other cases you should consider using 'safe_load(stream)'
  data = yaml.load(stream)

Rasa Core server is up and running on http://localhost:5005
Rasa process starting
Rasa process starting
/home/hticdeep/anaconda3/envs/torch3/lib/python3.6/site-packages/rasa_nlu/extractors/entity_synonyms.py:85: UserWarning: Failed to load synonyms file from '/media/hticdeep/drive3/shyam/IDAI/RASA/Gere_version2/models/nlu/default/GereV2/entity_synonyms.json'
  "".format(entity_synonyms_file))

Restoring parameters from /media/hticdeep/drive3/shyam/IDAI/RASA/Gere_version2/models/nlu/default/GereV2/intent_classifier_tensorflow_embedding.ckpt
/home/hticdeep/anaconda3/envs/torch3/lib/python3.6/site-packages/pykwalify/core.py:99: UnsafeLoaderWarning: 
The default 'Loader' for 'load(stream)' without further arguments can be unsafe.
Use 'load(stream, Loader=ruamel.yaml.Loader)' explicitly if that is OK.
Alternatively include the following in your code:

  import warnings
  warnings.simplefilter('ignore', ruamel.yaml.error.UnsafeLoaderWarning)

In most other cases you should consider using 'safe_load(stream)'
  data = yaml.load(stream)

Rasa Core server is up and running on http://localhost:5005
Rasa process starting
/home/hticdeep/anaconda3/envs/torch3/lib/python3.6/site-packages/rasa_nlu/extractors/entity_synonyms.py:85: UserWarning: Failed to load synonyms file from '/media/hticdeep/drive3/shyam/IDAI/RASA/Gere_version2/models/nlu/default/GereV2/entity_synonyms.json'
  "".format(entity_synonyms_file))

Restoring parameters from /media/hticdeep/drive3/shyam/IDAI/RASA/Gere_version2/models/nlu/default/GereV2/intent_classifier_tensorflow_embedding.ckpt
/home/hticdeep/anaconda3/envs/torch3/lib/python3.6/site-packages/pykwalify/core.py:99: UnsafeLoaderWarning: 
The default 'Loader' for 'load(stream)' without further arguments can be unsafe.
Use 'load(stream, Loader=ruamel.yaml.Loader)' explicitly if that is OK.
Alternatively include the following in your code:

  import warnings
  warnings.simplefilter('ignore', ruamel.yaml.error.UnsafeLoaderWarning)

In most other cases you should consider using 'safe_load(stream)'
  data = yaml.load(stream)

Rasa Core server is up and running on http://localhost:5005
Rasa process starting
/home/hticdeep/anaconda3/envs/torch3/lib/python3.6/site-packages/rasa_nlu/extractors/entity_synonyms.py:85: UserWarning: Failed to load synonyms file from '/media/hticdeep/drive3/shyam/IDAI/RASA/Gere_version2/models/nlu/default/GereV2/entity_synonyms.json'
  "".format(entity_synonyms_file))

Restoring parameters from /media/hticdeep/drive3/shyam/IDAI/RASA/Gere_version2/models/nlu/default/GereV2/intent_classifier_tensorflow_embedding.ckpt
/home/hticdeep/anaconda3/envs/torch3/lib/python3.6/site-packages/pykwalify/core.py:99: UnsafeLoaderWarning: 
The default 'Loader' for 'load(stream)' without further arguments can be unsafe.
Use 'load(stream, Loader=ruamel.yaml.Loader)' explicitly if that is OK.
Alternatively include the following in your code:

  import warnings
  warnings.simplefilter('ignore', ruamel.yaml.error.UnsafeLoaderWarning)

In most other cases you should consider using 'safe_load(stream)'
  data = yaml.load(stream)

Rasa Core server is up and running on http://localhost:5005
Rasa process starting
/home/hticdeep/anaconda3/envs/torch3/lib/python3.6/site-packages/pykwalify/core.py:99: UnsafeLoaderWarning: 
The default 'Loader' for 'load(stream)' without further arguments can be unsafe.
Use 'load(stream, Loader=ruamel.yaml.Loader)' explicitly if that is OK.
Alternatively include the following in your code:

  import warnings
  warnings.simplefilter('ignore', ruamel.yaml.error.UnsafeLoaderWarning)

In most other cases you should consider using 'safe_load(stream)'
  data = yaml.load(stream)

Rasa Core server is up and running on http://localhost:5005
Rasa process starting
/home/hticdeep/anaconda3/envs/torch3/lib/python3.6/site-packages/pykwalify/core.py:99: UnsafeLoaderWarning: 
The default 'Loader' for 'load(stream)' without further arguments can be unsafe.
Use 'load(stream, Loader=ruamel.yaml.Loader)' explicitly if that is OK.
Alternatively include the following in your code:

  import warnings
  warnings.simplefilter('ignore', ruamel.yaml.error.UnsafeLoaderWarning)

In most other cases you should consider using 'safe_load(stream)'
  data = yaml.load(stream)

Rasa Core server is up and running on http://localhost:5005
Rasa process starting
/home/hticdeep/anaconda3/envs/torch3/lib/python3.6/site-packages/pykwalify/core.py:99: UnsafeLoaderWarning: 
The default 'Loader' for 'load(stream)' without further arguments can be unsafe.
Use 'load(stream, Loader=ruamel.yaml.Loader)' explicitly if that is OK.
Alternatively include the following in your code:

  import warnings
  warnings.simplefilter('ignore', ruamel.yaml.error.UnsafeLoaderWarning)

In most other cases you should consider using 'safe_load(stream)'
  data = yaml.load(stream)

Rasa Core server is up and running on http://localhost:5005
Rasa process starting
/home/hticdeep/anaconda3/envs/torch3/lib/python3.6/site-packages/pykwalify/core.py:99: UnsafeLoaderWarning: 
The default 'Loader' for 'load(stream)' without further arguments can be unsafe.
Use 'load(stream, Loader=ruamel.yaml.Loader)' explicitly if that is OK.
Alternatively include the following in your code:

  import warnings
  warnings.simplefilter('ignore', ruamel.yaml.error.UnsafeLoaderWarning)

In most other cases you should consider using 'safe_load(stream)'
  data = yaml.load(stream)

Rasa process starting
/home/hticdeep/anaconda3/envs/torch3/lib/python3.6/site-packages/pykwalify/core.py:99: UnsafeLoaderWarning: 
The default 'Loader' for 'load(stream)' without further arguments can be unsafe.
Use 'load(stream, Loader=ruamel.yaml.Loader)' explicitly if that is OK.
Alternatively include the following in your code:

  import warnings
  warnings.simplefilter('ignore', ruamel.yaml.error.UnsafeLoaderWarning)

In most other cases you should consider using 'safe_load(stream)'
  data = yaml.load(stream)

Rasa Core server is up and running on http://localhost:5005
Rasa process starting
/home/hticdeep/anaconda3/envs/torch3/lib/python3.6/site-packages/pykwalify/core.py:99: UnsafeLoaderWarning: 
The default 'Loader' for 'load(stream)' without further arguments can be unsafe.
Use 'load(stream, Loader=ruamel.yaml.Loader)' explicitly if that is OK.
Alternatively include the following in your code:

  import warnings
  warnings.simplefilter('ignore', ruamel.yaml.error.UnsafeLoaderWarning)

In most other cases you should consider using 'safe_load(stream)'
  data = yaml.load(stream)

Rasa Core server is up and running on http://localhost:5005
Failed to run custom action 'action_slots2'. Couldn't connect to the server at 'http://localhost:5000/webhook/'. Is the server running? Error: HTTPConnectionPool(host='localhost', port=5000): Max retries exceeded with url: /webhook/ (Caused by NewConnectionError('<urllib3.connection.HTTPConnection object at 0x7f966c5cf160>: Failed to establish a new connection: [Errno 111] Connection refused',))
Encountered an exception while running action 'action_slots2'. Bot will continue, but the actions events are lost. Make sure to fix the exception in your custom code.
Failed to execute custom action.
Traceback (most recent call last):
  File "/home/hticdeep/anaconda3/envs/torch3/lib/python3.6/site-packages/urllib3/connection.py", line 171, in _new_conn
    (self._dns_host, self.port), self.timeout, **extra_kw)
  File "/home/hticdeep/anaconda3/envs/torch3/lib/python3.6/site-packages/urllib3/util/connection.py", line 79, in create_connection
    raise err
  File "/home/hticdeep/anaconda3/envs/torch3/lib/python3.6/site-packages/urllib3/util/connection.py", line 69, in create_connection
    sock.connect(sa)
ConnectionRefusedError: [Errno 111] Connection refused

During handling of the above exception, another exception occurred:

Traceback (most recent call last):
  File "/home/hticdeep/anaconda3/envs/torch3/lib/python3.6/site-packages/urllib3/connectionpool.py", line 600, in urlopen
    chunked=chunked)
  File "/home/hticdeep/anaconda3/envs/torch3/lib/python3.6/site-packages/urllib3/connectionpool.py", line 354, in _make_request
    conn.request(method, url, **httplib_request_kw)
  File "/home/hticdeep/anaconda3/envs/torch3/lib/python3.6/http/client.py", line 1239, in request
    self._send_request(method, url, body, headers, encode_chunked)
  File "/home/hticdeep/anaconda3/envs/torch3/lib/python3.6/http/client.py", line 1285, in _send_request
    self.endheaders(body, encode_chunked=encode_chunked)
  File "/home/hticdeep/anaconda3/envs/torch3/lib/python3.6/http/client.py", line 1234, in endheaders
    self._send_output(message_body, encode_chunked=encode_chunked)
  File "/home/hticdeep/anaconda3/envs/torch3/lib/python3.6/http/client.py", line 1026, in _send_output
    self.send(msg)
  File "/home/hticdeep/anaconda3/envs/torch3/lib/python3.6/http/client.py", line 964, in send
    self.connect()
  File "/home/hticdeep/anaconda3/envs/torch3/lib/python3.6/site-packages/urllib3/connection.py", line 196, in connect
    conn = self._new_conn()
  File "/home/hticdeep/anaconda3/envs/torch3/lib/python3.6/site-packages/urllib3/connection.py", line 180, in _new_conn
    self, "Failed to establish a new connection: %s" % e)
urllib3.exceptions.NewConnectionError: <urllib3.connection.HTTPConnection object at 0x7f966c5cf160>: Failed to establish a new connection: [Errno 111] Connection refused

During handling of the above exception, another exception occurred:

Traceback (most recent call last):
  File "/home/hticdeep/anaconda3/envs/torch3/lib/python3.6/site-packages/requests/adapters.py", line 449, in send
    timeout=timeout
  File "/home/hticdeep/anaconda3/envs/torch3/lib/python3.6/site-packages/urllib3/connectionpool.py", line 638, in urlopen
    _stacktrace=sys.exc_info()[2])
  File "/home/hticdeep/anaconda3/envs/torch3/lib/python3.6/site-packages/urllib3/util/retry.py", line 398, in increment
    raise MaxRetryError(_pool, url, error or ResponseError(cause))
urllib3.exceptions.MaxRetryError: HTTPConnectionPool(host='localhost', port=5000): Max retries exceeded with url: /webhook/ (Caused by NewConnectionError('<urllib3.connection.HTTPConnection object at 0x7f966c5cf160>: Failed to establish a new connection: [Errno 111] Connection refused',))

During handling of the above exception, another exception occurred:

Traceback (most recent call last):
  File "/home/hticdeep/anaconda3/envs/torch3/lib/python3.6/site-packages/rasa_core/actions/action.py", line 327, in run
    json=json, method="post", timeout=DEFAULT_REQUEST_TIMEOUT)
  File "/home/hticdeep/anaconda3/envs/torch3/lib/python3.6/site-packages/rasa_core/utils.py", line 748, in request
    **kwargs)
  File "/home/hticdeep/anaconda3/envs/torch3/lib/python3.6/site-packages/requests/api.py", line 60, in request
    return session.request(method=method, url=url, **kwargs)
  File "/home/hticdeep/anaconda3/envs/torch3/lib/python3.6/site-packages/requests/sessions.py", line 533, in request
    resp = self.send(prep, **send_kwargs)
  File "/home/hticdeep/anaconda3/envs/torch3/lib/python3.6/site-packages/requests/sessions.py", line 646, in send
    r = adapter.send(request, **kwargs)
  File "/home/hticdeep/anaconda3/envs/torch3/lib/python3.6/site-packages/requests/adapters.py", line 516, in send
    raise ConnectionError(e, request=request)
requests.exceptions.ConnectionError: HTTPConnectionPool(host='localhost', port=5000): Max retries exceeded with url: /webhook/ (Caused by NewConnectionError('<urllib3.connection.HTTPConnection object at 0x7f966c5cf160>: Failed to establish a new connection: [Errno 111] Connection refused',))

During handling of the above exception, another exception occurred:

Traceback (most recent call last):
  File "/home/hticdeep/anaconda3/envs/torch3/lib/python3.6/site-packages/rasa_core/processor.py", line 351, in _run_action
    events = action.run(dispatcher, tracker, self.domain)
  File "/home/hticdeep/anaconda3/envs/torch3/lib/python3.6/site-packages/rasa_core/actions/action.py", line 348, in run
    raise Exception("Failed to execute custom action.")
Exception: Failed to execute custom action.
Rasa process starting
/home/hticdeep/anaconda3/envs/torch3/lib/python3.6/site-packages/pykwalify/core.py:99: UnsafeLoaderWarning: 
The default 'Loader' for 'load(stream)' without further arguments can be unsafe.
Use 'load(stream, Loader=ruamel.yaml.Loader)' explicitly if that is OK.
Alternatively include the following in your code:

  import warnings
  warnings.simplefilter('ignore', ruamel.yaml.error.UnsafeLoaderWarning)

In most other cases you should consider using 'safe_load(stream)'
  data = yaml.load(stream)

Rasa Core server is up and running on http://localhost:5005
Failed to run custom action 'action_slots2'. Couldn't connect to the server at 'http://localhost:5000/webhook/'. Is the server running? Error: HTTPConnectionPool(host='localhost', port=5000): Max retries exceeded with url: /webhook/ (Caused by NewConnectionError('<urllib3.connection.HTTPConnection object at 0x7f37080e4cf8>: Failed to establish a new connection: [Errno 111] Connection refused',))
Encountered an exception while running action 'action_slots2'. Bot will continue, but the actions events are lost. Make sure to fix the exception in your custom code.
Failed to execute custom action.
Traceback (most recent call last):
  File "/home/hticdeep/anaconda3/envs/torch3/lib/python3.6/site-packages/urllib3/connection.py", line 171, in _new_conn
    (self._dns_host, self.port), self.timeout, **extra_kw)
  File "/home/hticdeep/anaconda3/envs/torch3/lib/python3.6/site-packages/urllib3/util/connection.py", line 79, in create_connection
    raise err
  File "/home/hticdeep/anaconda3/envs/torch3/lib/python3.6/site-packages/urllib3/util/connection.py", line 69, in create_connection
    sock.connect(sa)
ConnectionRefusedError: [Errno 111] Connection refused

During handling of the above exception, another exception occurred:

Traceback (most recent call last):
  File "/home/hticdeep/anaconda3/envs/torch3/lib/python3.6/site-packages/urllib3/connectionpool.py", line 600, in urlopen
    chunked=chunked)
  File "/home/hticdeep/anaconda3/envs/torch3/lib/python3.6/site-packages/urllib3/connectionpool.py", line 354, in _make_request
    conn.request(method, url, **httplib_request_kw)
  File "/home/hticdeep/anaconda3/envs/torch3/lib/python3.6/http/client.py", line 1239, in request
    self._send_request(method, url, body, headers, encode_chunked)
  File "/home/hticdeep/anaconda3/envs/torch3/lib/python3.6/http/client.py", line 1285, in _send_request
    self.endheaders(body, encode_chunked=encode_chunked)
  File "/home/hticdeep/anaconda3/envs/torch3/lib/python3.6/http/client.py", line 1234, in endheaders
    self._send_output(message_body, encode_chunked=encode_chunked)
  File "/home/hticdeep/anaconda3/envs/torch3/lib/python3.6/http/client.py", line 1026, in _send_output
    self.send(msg)
  File "/home/hticdeep/anaconda3/envs/torch3/lib/python3.6/http/client.py", line 964, in send
    self.connect()
  File "/home/hticdeep/anaconda3/envs/torch3/lib/python3.6/site-packages/urllib3/connection.py", line 196, in connect
    conn = self._new_conn()
  File "/home/hticdeep/anaconda3/envs/torch3/lib/python3.6/site-packages/urllib3/connection.py", line 180, in _new_conn
    self, "Failed to establish a new connection: %s" % e)
urllib3.exceptions.NewConnectionError: <urllib3.connection.HTTPConnection object at 0x7f37080e4cf8>: Failed to establish a new connection: [Errno 111] Connection refused

During handling of the above exception, another exception occurred:

Traceback (most recent call last):
  File "/home/hticdeep/anaconda3/envs/torch3/lib/python3.6/site-packages/requests/adapters.py", line 449, in send
    timeout=timeout
  File "/home/hticdeep/anaconda3/envs/torch3/lib/python3.6/site-packages/urllib3/connectionpool.py", line 638, in urlopen
    _stacktrace=sys.exc_info()[2])
  File "/home/hticdeep/anaconda3/envs/torch3/lib/python3.6/site-packages/urllib3/util/retry.py", line 398, in increment
    raise MaxRetryError(_pool, url, error or ResponseError(cause))
urllib3.exceptions.MaxRetryError: HTTPConnectionPool(host='localhost', port=5000): Max retries exceeded with url: /webhook/ (Caused by NewConnectionError('<urllib3.connection.HTTPConnection object at 0x7f37080e4cf8>: Failed to establish a new connection: [Errno 111] Connection refused',))

During handling of the above exception, another exception occurred:

Traceback (most recent call last):
  File "/home/hticdeep/anaconda3/envs/torch3/lib/python3.6/site-packages/rasa_core/actions/action.py", line 327, in run
    json=json, method="post", timeout=DEFAULT_REQUEST_TIMEOUT)
  File "/home/hticdeep/anaconda3/envs/torch3/lib/python3.6/site-packages/rasa_core/utils.py", line 748, in request
    **kwargs)
  File "/home/hticdeep/anaconda3/envs/torch3/lib/python3.6/site-packages/requests/api.py", line 60, in request
    return session.request(method=method, url=url, **kwargs)
  File "/home/hticdeep/anaconda3/envs/torch3/lib/python3.6/site-packages/requests/sessions.py", line 533, in request
    resp = self.send(prep, **send_kwargs)
  File "/home/hticdeep/anaconda3/envs/torch3/lib/python3.6/site-packages/requests/sessions.py", line 646, in send
    r = adapter.send(request, **kwargs)
  File "/home/hticdeep/anaconda3/envs/torch3/lib/python3.6/site-packages/requests/adapters.py", line 516, in send
    raise ConnectionError(e, request=request)
requests.exceptions.ConnectionError: HTTPConnectionPool(host='localhost', port=5000): Max retries exceeded with url: /webhook/ (Caused by NewConnectionError('<urllib3.connection.HTTPConnection object at 0x7f37080e4cf8>: Failed to establish a new connection: [Errno 111] Connection refused',))

During handling of the above exception, another exception occurred:

Traceback (most recent call last):
  File "/home/hticdeep/anaconda3/envs/torch3/lib/python3.6/site-packages/rasa_core/processor.py", line 351, in _run_action
    events = action.run(dispatcher, tracker, self.domain)
  File "/home/hticdeep/anaconda3/envs/torch3/lib/python3.6/site-packages/rasa_core/actions/action.py", line 348, in run
    raise Exception("Failed to execute custom action.")
Exception: Failed to execute custom action.
